[32m2024-02-17 12:06:02 +0100[0m - dagster - [34mDEBUG[0m - __ASSET_JOB - a666a105-d18b-4a38-a91e-43256eb3e402 - 7691 - LOGS_CAPTURED - Started capturing logs in process (pid: 7691).
[32m2024-02-17 12:06:02 +0100[0m - dagster - [34mDEBUG[0m - __ASSET_JOB - a666a105-d18b-4a38-a91e-43256eb3e402 - 7691 - tweetInformation - STEP_START - Started execution of step "tweetInformation".
[32m2024-02-17 12:06:03 +0100[0m - dagster - [34mERROR[0m - [31m__ASSET_JOB - a666a105-d18b-4a38-a91e-43256eb3e402 - 7691 - tweetInformation - STEP_FAILURE - Execution of step "tweetInformation" failed.

dagster._core.errors.DagsterExecutionStepExecutionError: Error occurred while executing op "tweetInformation"::

TypeError: not all arguments converted during string formatting

Stack Trace:
  File "/Users/hamza.haleem/Projects/Tweet_Data_Pipeline/venv/lib/python3.10/site-packages/dagster/_core/execution/plan/utils.py", line 54, in op_execution_error_boundary
    yield
  File "/Users/hamza.haleem/Projects/Tweet_Data_Pipeline/venv/lib/python3.10/site-packages/dagster/_utils/__init__.py", line 465, in iterate_with_context
    next_output = next(iterator)
  File "/Users/hamza.haleem/Projects/Tweet_Data_Pipeline/venv/lib/python3.10/site-packages/dagster/_core/execution/plan/compute.py", line 145, in gen_from_async_gen
    yield loop.run_until_complete(async_gen.__anext__())
  File "/Library/Frameworks/Python.framework/Versions/3.10/lib/python3.10/asyncio/base_events.py", line 649, in run_until_complete
    return future.result()
  File "/Users/hamza.haleem/Projects/Tweet_Data_Pipeline/venv/lib/python3.10/site-packages/dagster/_core/execution/plan/compute_generator.py", line 100, in _coerce_async_op_to_async_gen
    result = await awaitable
  File "/Users/hamza.haleem/Projects/Tweet_Data_Pipeline/tweet_data_pipeline/assets.py", line 10, in tweetInformation
    await getTweets(env_set, connector)
  File "/Users/hamza.haleem/Projects/Tweet_Data_Pipeline/tweet_data_pipeline/twitter/tweets.py", line 53, in getTweets
    logger.error("Status Failed On,", str(e))
  File "/Library/Frameworks/Python.framework/Versions/3.10/lib/python3.10/logging/__init__.py", line 1506, in error
    self._log(ERROR, msg, args, **kwargs)
  File "/Library/Frameworks/Python.framework/Versions/3.10/lib/python3.10/logging/__init__.py", line 1624, in _log
    self.handle(record)
  File "/Library/Frameworks/Python.framework/Versions/3.10/lib/python3.10/logging/__init__.py", line 1634, in handle
    self.callHandlers(record)
  File "/Library/Frameworks/Python.framework/Versions/3.10/lib/python3.10/logging/__init__.py", line 1696, in callHandlers
    hdlr.handle(record)
  File "/Library/Frameworks/Python.framework/Versions/3.10/lib/python3.10/logging/__init__.py", line 968, in handle
    self.emit(record)
  File "/Users/hamza.haleem/Projects/Tweet_Data_Pipeline/venv/lib/python3.10/site-packages/dagster/_core/log_manager.py", line 284, in emit
    dagster_record = self._convert_record(record)
  File "/Users/hamza.haleem/Projects/Tweet_Data_Pipeline/venv/lib/python3.10/site-packages/dagster/_core/log_manager.py", line 250, in _convert_record
    orig_message=record.getMessage(), dagster_event=dagster_meta
  File "/Library/Frameworks/Python.framework/Versions/3.10/lib/python3.10/logging/__init__.py", line 368, in getMessage
    msg = msg % self.args

The above exception occurred during handling of the following exception:
tweepy.errors.Forbidden: 403 Forbidden
453 - You currently have access to a subset of Twitter API v2 endpoints and limited v1.1 endpoints (e.g. media post, oauth) only. If you need access to this endpoint, you may need a different access level. You can learn more here: https://developer.twitter.com/en/portal/product

Stack Trace:
  File "/Users/hamza.haleem/Projects/Tweet_Data_Pipeline/tweet_data_pipeline/twitter/tweets.py", line 27, in getTweets
    tweets = api.search_tweets(
  File "/Users/hamza.haleem/Projects/Tweet_Data_Pipeline/venv/lib/python3.10/site-packages/tweepy/api.py", line 33, in wrapper
    return method(*args, **kwargs)
  File "/Users/hamza.haleem/Projects/Tweet_Data_Pipeline/venv/lib/python3.10/site-packages/tweepy/api.py", line 46, in wrapper
    return method(*args, **kwargs)
  File "/Users/hamza.haleem/Projects/Tweet_Data_Pipeline/venv/lib/python3.10/site-packages/tweepy/api.py", line 1146, in search_tweets
    return self.request(
  File "/Users/hamza.haleem/Projects/Tweet_Data_Pipeline/venv/lib/python3.10/site-packages/tweepy/api.py", line 271, in request
    raise Forbidden(resp)
[0m
